Workbook

Sheet Read Me
A1: Mood Tracker Symptom Items: ADHD and Bipolar
A3: What this is
A4: Starter lists of ADHD and bipolar disorder symptoms plus general health items, each tagged with a suggested input type for a mood tracker app. Edit freely: change wording, swap input types, or delete rows.
A6: Tabs
A7: ADHD Symptoms / ADHD Summary: 64 items for ADHD, with counts by input type and category.
A8: Bipolar Symptoms / Bipolar Summary: items for bipolar disorder (manic/hypomanic, depressive, mixed features, sleep, safety check-in, context), with the same counts.
A9: Cross-Reference: every item from both lists placed in one of three sections: ADHD only, Bipolar only, or Either / general health. Overlap rows show how each condition tends to differ.
A11: How the columns work
A12: Input Type: Slider = rate on a 0-10 scale; Radio = pick one option; Checkbox = tick if it happened today. Change it using the dropdown; the summaries update automatically.
A13: Scale / Options: for sliders, the end labels; for radio, the options separated by ' | '; for checkboxes, what a tick means.
A14: Higher Score Means: whether a higher value is worse (symptom) or better (e.g. energy, sleep). Bipolar items also say which pole they belong to (elevated or depressive).
A16: Where the items come from
... A22: This is for self-tracking and pattern-spotting, not for diagnosis. The bipolar list includes a 'thoughts of death or harming myself' item (Safety Check-in). The app should respond to any positive answer with crisis resources (US: call or text 988) rather than only logging it.

Sheet ADHD Symptoms
A1: ID | B1: Category | C1: Symptom / Prompt (as shown in app) | D1: Input Type | E1: Scale / Options | F1: Higher Score Means | G1: Notes
A2: S001 | B2: Inattention | C2: Difficulty sustaining focus on a task | D2: Slider | E2: 0 = Not at all, 10 = Severe | F2: Higher = more symptom | G2: DSM-5 inattention domain
A3: S002 | B3: Inattention | C3: Easily distracted by noises or things around me | D3: Slider | E3: 0 = Not at all, 10 = Severe | F3: Higher = more symptom | G3: DSM-5 inattention domain
A4: S003 | B4: Inattention | C4: Mind wandering during conversations or meetings | D4: Slider | E4: 0 = Not at all, 10 = Severe | F4: Higher = more symptom | G4: DSM-5 inattention domain
A5: S004 | B5: Inattention | C5: Zoned out when someone was talking to me | D5: Radio | E5: Not at all | Sometimes | Often | Very often | F5: Higher = more symptom | G5: DSM-5: 'does not seem to listen'
A6: S005 | B6: Inattention | C6: Careless mistakes or missed details | D6: Radio | E6: None | Mild | Moderate | Severe | F6: Higher = more symptom | G6: DSM-5 inattention domain
A7: S006 | B7: Inattention | C7: Trouble finishing things I started | D7: Slider | E7: 0 = Not at all, 10 = Severe | F7: Higher = more symptom | G7: DSM-5 inattention domain
A8: S007 | B8: Inattention | C8: Avoided tasks that need sustained mental effort | D8: Slider | E8: 0 = Not at all, 10 = Severe | F8: Higher = more symptom | G8: DSM-5 inattention domain
A9: S008 | B9: Inattention | C9: Lost or misplaced something important | D9: Checkbox | E9: Checked = happened today | F9: Higher = more symptom | G9: DSM-5 inattention domain
A10: S009 | B10: Inattention | C10: Forgot an appointment, task, or commitment | D10: Checkbox | E10: Checked = happened today | F10: Higher = more symptom | G10: DSM-5: forgetfulness in daily activities
A11: S010 | B11: Inattention | C11: Brain fog / mentally 'cloudy' | D11: Slider | E11: 0 = Not at all, 10 = Severe | F11: Higher = more symptom | G11: Commonly reported in adults
A12: S011 | B12: Inattention | C12: Hyperfocus (lost track of time on one thing) | D12: Radio | E12: None | Productive | Unproductive | Both | F12: n/a (descriptive) | G12: Not a DSM symptom, but common; useful for pattern spotting
A13: S012 | B13: Executive Function | C13: Trouble getting started on tasks | D13: Slider | E13: 0 = Not at all, 10 = Severe | F13: Higher = more symptom | G13: Task initiation / 'task paralysis'
A14: S013 | B14: Executive Function | C14: Procrastination | D14: Slider | E14: 0 = Not at all, 10 = Severe | F14: Higher = more symptom
A15: S014 | B15: Executive Function | C15: Trouble prioritizing what to do first | D15: Slider | E15: 0 = Not at all, 10 = Severe | F15: Higher = more symptom
A16: S015 | B16: Executive Function | C16: Difficulty planning or organizing | D16: Slider | E16: 0 = Not at all, 10 = Severe | F16: Higher = more symptom | G16: DSM-5: difficulty organizing tasks
A17: S016 | B17: Executive Function | C17: Felt overwhelmed by the number of things to do | D17: Slider | E17: 0 = Not at all, 10 = Severe | F17: Higher = more symptom
A18: S017 | B18: Executive Function | C18: Trouble switching from one task to another | D18: Slider | E18: 0 = Not at all, 10 = Severe | F18: Higher = more symptom | G18: Task shifting
A19: S018 | B19: Executive Function | C19: Forgot what I was about to do mid-task | D19: Radio | E19: 0 times | 1-2 times | 3-5 times | 6+ times | F19: Higher = more symptom | G19: Working memory
A20: S019 | B20: Executive Function | C20: Trouble following multi-step instructions | D20: Checkbox | E20: Checked = happened today | F20: Higher = more symptom | G20: DSM-5 inattention domain
A21: S020 | B21: Executive Function | C21: Lost track of time / ran late | D21: Radio | E21: On time | A little late | Very late | Missed it | F21: Higher = more symptom | G21: Time awareness
A22: S021 | B22: Executive Function | C22: Got through my must-do list today | D22: Radio | E22: None | Some | Most | All | F22: Higher = better | G22: Reverse-scored; gives a positive anchor
A23: S022 | B23: Hyperactivity / Restlessness | C23: Inner restlessness | D23: Slider | E23: 0 = Not at all, 10 = Severe | F23: Higher = more symptom | G23: In adults, hyperactivity often shows up as inner restlessness
A24: S023 | B24: Hyperactivity / Restlessness | C24: Racing or jumping thoughts | D24: Slider | E24: 0 = Not at all, 10 = Severe | F24: Higher = more symptom
A25: S024 | B25: Hyperactivity / Restlessness | C25: Fidgeting or tapping | D25: Slider | E25: 0 = Not at all, 10 = Severe | F25: Higher = more symptom | G25: DSM-5 hyperactivity domain
A26: S025 | B26: Hyperactivity / Restlessness | C26: Hard to sit still when I needed to | D26: Checkbox | E26: Checked = happened today | F26: Higher = more symptom | G26: DSM-5 hyperactivity domain
A27: S026 | B27: Hyperactivity / Restlessness | C27: Difficulty relaxing or winding down | D27: Slider | E27: 0 = Not at all, 10 = Severe | F27: Higher = more symptom | G27: DSM-5 hyperactivity domain
A28: S027 | B28: Hyperactivity / Restlessness | C28: Felt 'driven by a motor' | D28: Slider | E28: 0 = Not at all, 10 = Severe | F28: Higher = more symptom | G28: DSM-5 hyperactivity domain
A29: S028 | B29: Hyperactivity / Restlessness | C29: Talked more than I intended | D29: Radio | E29: Not at all | Sometimes | Often | Very often | F29: Higher = more symptom | G29: DSM-5 hyperactivity domain
A30: S029 | B30: Impulsivity | C30: Acted without thinking it through | D30: Slider | E30: 0 = Not at all, 10 = Severe | F30: Higher = more symptom | G30: DSM-5 impulsivity domain
A31: S030 | B31: Impulsivity | C31: Interrupted or blurted something out | D31: Checkbox | E31: Checked = happened today | F31: Higher = more symptom | G31: DSM-5 impulsivity domain
A32: S031 | B32: Impulsivity | C32: Trouble waiting my turn / waiting in line | D32: Slider | E32: 0 = Not at all, 10 = Severe | F32: Higher = more symptom | G32: DSM-5 impulsivity domain
A33: S032 | B33: Impulsivity | C33: Impulse purchase | D33: Checkbox | E33: Checked = happened today | F33: Higher = more symptom | G33: Common adult manifestation
A34: S033 | B34: Impulsivity | C34: Impulsive eating or snacking | D34: Checkbox | E34: Checked = happened today | F34: Higher = more symptom
A35: S034 | B35: Impulsivity | C35: Urge to drop what I was doing for something new | D35: Slider | E35: 0 = Not at all, 10 = Severe | F35: Higher = more symptom | G35: Seeking stimulation / novelty
A36: S035 | B36: Impulsivity | C36: Lost time to scrolling or screens | D36: Radio | E36: None | Under 1 hr | 1-3 hrs | 3+ hrs | F36: Higher = more symptom
A37: S036 | B37: Emotional Regulation | C37: Irritability | D37: Slider | E37: 0 = Not at all, 10 = Severe | F37: Higher = more symptom | G37: Emotional dyscontrol factor in adult ADHD research
A38: S037 | B38: Emotional Regulation | C38: Quick to feel frustrated | D38: Slider | E38: 0 = Not at all, 10 = Severe | F38: Higher = more symptom
A39: S038 | B39: Emotional Regulation | C39: Mood swings | D39: Radio | E39: None | Mild | Moderate | Severe | F39: Higher = more symptom
A40: S039 | B40: Emotional Regulation | C40: Emotionally overwhelmed | D40: Slider | E40: 0 = Not at all, 10 = Severe | F40: Higher = more symptom
...

Sheet ADHD Summary
A1: Symptom counts
A3: By input type
A4: Input Type | B4: Count
A5: Slider | B5: =COUNTIF('ADHD Symptoms'!$D$2:$D$65,A5) -> 35
A6: Radio | B6: =COUNTIF('ADHD Symptoms'!$D$2:$D$65,A6) -> 14
A7: Checkbox | B7: =COUNTIF('ADHD Symptoms'!$D$2:$D$65,A7) -> 15
A8: Total | B8: =SUM(B5:B7) -> 64
A10: By category
A11: Category | B11: Total | C11: Slider | D11: Radio | E11: Checkbox
A12: Inattention | B12: =COUNTIF('ADHD Symptoms'!$B$2:$B$65,A12) -> 11 | C12: =COUNTIFS('ADHD Symptoms'!$B$2:$B$65,$A12,'ADHD Symptoms'!$D$2:$D$65,C$11) -> 6 | D12: =COUNTIFS('ADHD Symptoms'!$B$2:$B$65,$A12,'ADHD Symptoms'!$D$2:$D$65,D$11) -> 3 | E12: =COUNTIFS('ADHD Symptoms'!$B$2:$B$65,$A12,'ADHD Symptoms'!$D$2:$D$65,E$11) -> 2
A13: Executive Function | B13: =COUNTIF('ADHD Symptoms'!$B$2:$B$65,A13) -> 10 | C13: =COUNTIFS('ADHD Symptoms'!$B$2:$B$65,$A13,'ADHD Symptoms'!$D$2:$D$65,C$11) -> 6 | D13: =COUNTIFS('ADHD Symptoms'!$B$2:$B$65,$A13,'ADHD Symptoms'!$D$2:$D$65,D$11) -> 3 | E13: =COUNTIFS('ADHD Symptoms'!$B$2:$B$65,$A13,'ADHD Symptoms'!$D$2:$D$65,E$11) -> 1
A14: Hyperactivity / Restlessness | B14: =COUNTIF('ADHD Symptoms'!$B$2:$B$65,A14) -> 7 | C14: =COUNTIFS('ADHD Symptoms'!$B$2:$B$65,$A14,'ADHD Symptoms'!$D$2:$D$65,C$11) -> 5 | D14: =COUNTIFS('ADHD Symptoms'!$B$2:$B$65,$A14,'ADHD Symptoms'!$D$2:$D$65,D$11) -> 1 | E14: =COUNTIFS('ADHD Symptoms'!$B$2:$B$65,$A14,'ADHD Symptoms'!$D$2:$D$65,E$11) -> 1
A15: Impulsivity | B15: =COUNTIF('ADHD Symptoms'!$B$2:$B$65,A15) -> 7 | C15: =COUNTIFS('ADHD Symptoms'!$B$2:$B$65,$A15,'ADHD Symptoms'!$D$2:$D$65,C$11) -> 3 | D15: =COUNTIFS('ADHD Symptoms'!$B$2:$B$65,$A15,'ADHD Symptoms'!$D$2:$D$65,D$11) -> 1 | E15: =COUNTIFS('ADHD Symptoms'!$B$2:$B$65,$A15,'ADHD Symptoms'!$D$2:$D$65,E$11) -> 3
A16: Emotional Regulation | B16: =COUNTIF('ADHD Symptoms'!$B$2:$B$65,A16) -> 10 | C16: =COUNTIFS('ADHD Symptoms'!$B$2:$B$65,$A16,'ADHD Symptoms'!$D$2:$D$65,C$11) -> 8 | D16: =COUNTIFS('ADHD Symptoms'!$B$2:$B$65,$A16,'ADHD Symptoms'!$D$2:$D$65,D$11) -> 1 | E16: =COUNTIFS('ADHD Symptoms'!$B$2:$B$65,$A16,'ADHD Symptoms'!$D$2:$D$65,E$11) -> 1
A17: Energy, Sleep & Body | B17: =COUNTIF('ADHD Symptoms'!$B$2:$B$65,A17) -> 8 | C17: =COUNTIFS('ADHD Symptoms'!$B$2:$B$65,$A17,'ADHD Symptoms'!$D$2:$D$65,C$11) -> 5 | D17: =COUNTIFS('ADHD Symptoms'!$B$2:$B$65,$A17,'ADHD Symptoms'!$D$2:$D$65,D$11) -> 1 | E17: =COUNTIFS('ADHD Symptoms'!$B$2:$B$65,$A17,'ADHD Symptoms'!$D$2:$D$65,E$11) -> 2
A18: Context & Triggers | B18: =COUNTIF('ADHD Symptoms'!$B$2:$B$65,A18) -> 8 | C18: =COUNTIFS('ADHD Symptoms'!$B$2:$B$65,$A18,'ADHD Symptoms'!$D$2:$D$65,C$11) -> 0 | D18: =COUNTIFS('ADHD Symptoms'!$B$2:$B$65,$A18,'ADHD Symptoms'!$D$2:$D$65,D$11) -> 3 | E18: =COUNTIFS('ADHD Symptoms'!$B$2:$B$65,$A18,'ADHD Symptoms'!$D$2:$D$65,E$11) -> 5
A19: Overall Check-in | B19: =COUNTIF('ADHD Symptoms'!$B$2:$B$65,A19) -> 3 | C19: =COUNTIFS('ADHD Symptoms'!$B$2:$B$65,$A19,'ADHD Symptoms'!$D$2:$D$65,C$11) -> 2 | D19: =COUNTIFS('ADHD Symptoms'!$B$2:$B$65,$A19,'ADHD Symptoms'!$D$2:$D$65,D$11) -> 1 | E19: =COUNTIFS('ADHD Symptoms'!$B$2:$B$65,$A19,'ADHD Symptoms'!$D$2:$D$65,E$11) -> 0
A20: Total | B20: =SUM(B12:B19) -> 64 | C20: =SUM(C12:C19) -> 35 | D20: =SUM(D12:D19) -> 14 | E20: =SUM(E12:E19) -> 15

Sheet Bipolar Symptoms
A1: ID | B1: Category | C1: Symptom / Prompt (as shown in app) | D1: Input Type | E1: Scale / Options | F1: Higher Score Means | G1: Notes
A2: B001 | B2: Elevated Mood & Energy (Mania/Hypomania) | C2: Unusually happy, 'high,' or euphoric | D2: Slider | E2: 0 = Not at all, 10 = Severe | F2: Higher = more elevated (manic-pole) symptom | G2: DSM-5 manic/hypomanic episode: elevated or expansive mood
A3: B002 | B3: Elevated Mood & Energy (Mania/Hypomania) | C3: Felt unusually confident, powerful, or 'special' | D3: Slider | E3: 0 = Not at all, 10 = Severe | F3: Higher = more elevated (manic-pole) symptom | G3: DSM-5: inflated self-esteem or grandiosity
A4: B003 | B4: Elevated Mood & Energy (Mania/Hypomania) | C4: Much more energy than usual | D4: Slider | E4: 0 = Not at all, 10 = Severe | F4: Higher = more elevated (manic-pole) symptom | G4: DSM-5: increased energy or activity
A5: B004 | B5: Elevated Mood & Energy (Mania/Hypomania) | C5: Pushed hard on goals or projects (far more than usual) | D5: Slider | E5: 0 = Not at all, 10 = Severe | F5: Higher = more elevated (manic-pole) symptom | G5: DSM-5: increased goal-directed activity
A6: B005 | B6: Elevated Mood & Energy (Mania/Hypomania) | C6: Started several new projects or plans today | D6: Checkbox | E6: Checked = happened today | F6: Higher = more elevated (manic-pole) symptom | G6: Easy to spot in hindsight; useful for pattern spotting
A7: B006 | B7: Elevated Mood & Energy (Mania/Hypomania) | C7: Unusually creative or inspired | D7: Slider | E7: 0 = Not at all, 10 = Severe | F7: Higher = more elevated (manic-pole) symptom | G7: Commonly reported in hypomania; not a diagnostic criterion
A8: B007 | B8: Elevated Mood & Energy (Mania/Hypomania) | C8: Felt driven; couldn't slow down | D8: Slider | E8: 0 = Not at all, 10 = Severe | F8: Higher = more elevated (manic-pole) symptom | G8: Often described as feeling 'on' or 'revved up'
A9: B008 | B9: Thoughts & Speech | C9: Racing thoughts | D9: Slider | E9: 0 = Not at all, 10 = Severe | F9: Higher = more elevated (manic-pole) symptom | G9: DSM-5: racing thoughts / flight of ideas
A10: B009 | B10: Thoughts & Speech | C10: Jumped quickly from idea to idea | D10: Slider | E10: 0 = Not at all, 10 = Severe | F10: Higher = more elevated (manic-pole) symptom | G10: DSM-5: flight of ideas
A11: B010 | B11: Thoughts & Speech | C11: Talked faster or more than usual | D11: Radio | E11: Not at all | Sometimes | Often | Very often | F11: Higher = more elevated (manic-pole) symptom | G11: DSM-5: pressured speech
A12: B011 | B12: Thoughts & Speech | C12: Easily pulled off track by unimportant things | D12: Slider | E12: 0 = Not at all, 10 = Severe | F12: Higher = more elevated (manic-pole) symptom | G12: DSM-5 manic episode: distractibility
... A21: B020 | B21: Sleep | C21: Sleep quality last night | D21: Slider | E21: 0 = Very poor, 10 = Excellent | F21: Higher = better | G21: Reverse-scored
A22: B021 | B22: Risk-taking & Impulsivity | C22: Acted without thinking about consequences | D22: Slider | E22: 0 = Not at all, 10 = Severe | F22: Higher = more symptom
A23: B022 | B23: Risk-taking & Impulsivity | C23: Impulsive or excessive spending | D23: Checkbox | E23: Checked = happened today | F23: Higher = more elevated (manic-pole) symptom | G23: DSM-5: buying sprees as a risky activity
A24: B023 | B24: Risk-taking & Impulsivity | C24: Risky or reckless behavior (e.g., reckless driving, risky decisions) | D24: Checkbox | E24: Checked = happened today | F24: Higher = more elevated (manic-pole) symptom | G24: DSM-5: excessive involvement in risky activities. ADHD impulsivity can look similar, but is typically ongoing rather than in episodes
A25: B024 | B25: Risk-taking & Impulsivity | C25: Increased sexual interest or activity | D25: Slider | E25: 0 = Not at all, 10 = Severe | F25: Higher = more elevated (manic-pole) symptom | G25: Listed in DSM-5 under risky activities (sexual indiscretions)
A26: B025 | B26: Depressed Mood | C26: Low, sad, or empty mood | D26: Slider | E26: 0 = Not at all, 10 = Severe | F26: Higher = more depressive-pole symptom | G26: DSM-5 depressive episode
A27: B026 | B27: Depressed Mood | C27: Lost interest or pleasure in things I usually enjoy | D27: Slider | E27: 0 = Not at all, 10 = Severe | F27: Higher = more depressive-pole symptom | G27: DSM-5 depressive episode: anhedonia
A28: B027 | B28: Depressed Mood | C28: Felt hopeless about the future | D28: Slider | E28: 0 = Not at all, 10 = Severe | F28: Higher = more depressive-pole symptom
A29: B028 | B29: Depressed Mood | C29: Felt worthless or excessively guilty | D29: Slider | E29: 0 = Not at all, 10 = Severe | F29: Higher = more depressive-pole symptom | G29: DSM-5 depressive episode
A30: B029 | B30: Depressed Mood | C30: Crying spells or tearfulness | D30: Checkbox | E30: Checked = happened today | F30: Higher = more depressive-pole symptom
A31: B030 | B31: Depressed Mood | C31: Moved or spoke more slowly than usual | D31: Slider | E31: 0 = Not at all, 10 = Severe | F31: Higher = more depressive-pole symptom | G31: DSM-5: psychomotor retardation
A32: B031 | B32: Depressed Mood | C32: Withdrew from people or activities | D32: Slider | E32: 0 = Not at all, 10 = Severe | F32: Higher = more depressive-pole symptom
A33: B032 | B33: Depressed Mood | C33: Low motivation; hard to get started | D33: Slider | E33: 0 = Not at all, 10 = Severe | F33: Higher = more depressive-pole symptom
A34: B033 | B34: Anxiety, Agitation & Mixed Features | C34: Anxiety or worry | D34: Slider | E34: 0 = Not at all, 10 = Severe | F34: Higher = more symptom | G34: Common alongside both poles
A35: B034 | B35: Anxiety, Agitation & Mixed Features | C35: Irritable or short-tempered | D35: Slider | E35: 0 = Not at all, 10 = Severe | F35: Higher = more symptom | G35: Can occur in mania, depression, or mixed states
A36: B035 | B36: Anxiety, Agitation & Mixed Features | C36: Physically agitated or unable to sit still | D36: Slider | E36: 0 = Not at all, 10 = Severe | F36: Higher = more symptom | G36: DSM-5: psychomotor agitation
A37: B036 | B37: Anxiety, Agitation & Mixed Features | C37: Mood swings during the day | D37: Radio | E37: Not at all | Sometimes | Often | Very often | F37: Higher = more symptom | G37: Classic bipolar episodes last days or longer, but quick shifts can occur with mixed features or rapid cycling; useful to log either way
A38: B037 | B38: Anxiety, Agitation & Mixed Features | C38: 'Wired but tired': high energy and low mood at the same time | D38: Slider | E38: 0 = Not at all, 10 = Severe | F38: Higher = more symptom | G38: Mixed features (manic and depressive symptoms together)
A39: B038 | B39: Anxiety, Agitation & Mixed Features | C39: Anger outburst or lost my temper | D39: Checkbox | E39: Checked = happened today | F39: Higher = more symptom
A40: B039 | B40: Perception & Insight | C40: Unusual beliefs or experiences (e.g., hearing or seeing things others didn't, strongly held unusual ideas) | D40: Checkbox | E40: Checked = happened today | F40: Higher = more symptom | G40: Psychotic features can occur in severe episodes. If checked, the app could suggest contacting the care team
A41: B040 | B41: Perception & Insight | C41: Others said I seemed 'off' or unlike myself | D41: Checkbox | E41: Checked = happened today | F41: Higher = more symptom | G41: Often an early-warning sign; others may notice changes before the person does
A42: B041 | B42: Safety Check-in | C42: Thoughts of death, or of harming myself | D42: Radio | E42: None | Passing | Frequent | Strong, or with a plan | F42: Higher = more concerning | G42: Standard item in mood tracking. If anything other than 'None' is chosen, the app should show crisis resources (US: call or text 988) rather than only logging it. Not a substitute for care
A43: B042 | B43: Energy, Body & Context | C43: Energy level | D43: Slider | E43: 0 = Very low, 10 = Very high | F43: Higher = better | G43: Reverse-scored
A44: B043 | B44: Energy, Body & Context | C44: Fatigue or loss of energy | D44: Slider | E44: 0 = Not at all, 10 = Severe | F44: Higher = more depressive-pole symptom | G44: DSM-5 depressive episode
A45: B044 | B45: Energy, Body & Context | C45: Appetite | D45: Radio | E45: Low | Normal | High | Forgot to eat | F45: n/a (context) | G45: Appetite change can go either direction
A46: B045 | B46: Energy, Body & Context | C46: Took medication as planned | D46: Radio | E46: Yes | Partly | No | Not applicable | F46: n/a (context) | G46: Only relevant if the user has a medication plan
A47: B046 | B47: Energy, Body & Context | C47: Alcohol or other substances today | D47: Radio | E47: None | Some | A lot | F47: n/a (context) | G47: Substance use can affect mood stability
A48: B047 | B48: Energy, Body & Context | C48: Caffeine today | D48: Radio | E48: None | 1 serving | 2-3 servings | 4+ servings | F48: n/a (context)
...

Sheet Bipolar Summary
A1: Symptom counts
A3: By input type
A4: Input Type | B4: Count
A5: Slider | B5: =COUNTIF('Bipolar Symptoms'!$D$2:$D$57,A5) -> 30
A6: Radio | B6: =COUNTIF('Bipolar Symptoms'!$D$2:$D$57,A6) -> 11
A7: Checkbox | B7: =COUNTIF('Bipolar Symptoms'!$D$2:$D$57,A7) -> 15
A8: Total | B8: =SUM(B5:B7) -> 56
A10: By category
A11: Category | B11: Total | C11: Slider | D11: Radio | E11: Checkbox
A12: Elevated Mood & Energy (Mania/Hypomania) | B12: =COUNTIF('Bipolar Symptoms'!$B$2:$B$57,A12) -> 7 | C12: =COUNTIFS('Bipolar Symptoms'!$B$2:$B$57,$A12,'Bipolar Symptoms'!$D$2:$D$57,C$11) -> 6 | D12: =COUNTIFS('Bipolar Symptoms'!$B$2:$B$57,$A12,'Bipolar Symptoms'!$D$2:$D$57,D$11) -> 0 | E12: =COUNTIFS('Bipolar Symptoms'!$B$2:$B$57,$A12,'Bipolar Symptoms'!$D$2:$D$57,E$11) -> 1
A13: Thoughts & Speech | B13: =COUNTIF('Bipolar Symptoms'!$B$2:$B$57,A13) -> 8 | C13: =COUNTIFS('Bipolar Symptoms'!$B$2:$B$57,$A13,'Bipolar Symptoms'!$D$2:$D$57,C$11) -> 6 | D13: =COUNTIFS('Bipolar Symptoms'!$B$2:$B$57,$A13,'Bipolar Symptoms'!$D$2:$D$57,D$11) -> 1 | E13: =COUNTIFS('Bipolar Symptoms'!$B$2:$B$57,$A13,'Bipolar Symptoms'!$D$2:$D$57,E$11) -> 1
A14: Sleep | B14: =COUNTIF('Bipolar Symptoms'!$B$2:$B$57,A14) -> 5 | C14: =COUNTIFS('Bipolar Symptoms'!$B$2:$B$57,$A14,'Bipolar Symptoms'!$D$2:$D$57,C$11) -> 1 | D14: =COUNTIFS('Bipolar Symptoms'!$B$2:$B$57,$A14,'Bipolar Symptoms'!$D$2:$D$57,D$11) -> 1 | E14: =COUNTIFS('Bipolar Symptoms'!$B$2:$B$57,$A14,'Bipolar Symptoms'!$D$2:$D$57,E$11) -> 3
A15: Risk-taking & Impulsivity | B15: =COUNTIF('Bipolar Symptoms'!$B$2:$B$57,A15) -> 4 | C15: =COUNTIFS('Bipolar Symptoms'!$B$2:$B$57,$A15,'Bipolar Symptoms'!$D$2:$D$57,C$11) -> 2 | D15: =COUNTIFS('Bipolar Symptoms'!$B$2:$B$57,$A15,'Bipolar Symptoms'!$D$2:$D$57,D$11) -> 0 | E15: =COUNTIFS('Bipolar Symptoms'!$B$2:$B$57,$A15,'Bipolar Symptoms'!$D$2:$D$57,E$11) -> 2
A16: Depressed Mood | B16: =COUNTIF('Bipolar Symptoms'!$B$2:$B$57,A16) -> 8 | C16: =COUNTIFS('Bipolar Symptoms'!$B$2:$B$57,$A16,'Bipolar Symptoms'!$D$2:$D$57,C$11) -> 7 | D16: =COUNTIFS('Bipolar Symptoms'!$B$2:$B$57,$A16,'Bipolar Symptoms'!$D$2:$D$57,D$11) -> 0 | E16: =COUNTIFS('Bipolar Symptoms'!$B$2:$B$57,$A16,'Bipolar Symptoms'!$D$2:$D$57,E$11) -> 1
A17: Anxiety, Agitation & Mixed Features | B17: =COUNTIF('Bipolar Symptoms'!$B$2:$B$57,A17) -> 6 | C17: =COUNTIFS('Bipolar Symptoms'!$B$2:$B$57,$A17,'Bipolar Symptoms'!$D$2:$D$57,C$11) -> 4 | D17: =COUNTIFS('Bipolar Symptoms'!$B$2:$B$57,$A17,'Bipolar Symptoms'!$D$2:$D$57,D$11) -> 1 | E17: =COUNTIFS('Bipolar Symptoms'!$B$2:$B$57,$A17,'Bipolar Symptoms'!$D$2:$D$57,E$11) -> 1
A18: Perception & Insight | B18: =COUNTIF('Bipolar Symptoms'!$B$2:$B$57,A18) -> 2 | C18: =COUNTIFS('Bipolar Symptoms'!$B$2:$B$57,$A18,'Bipolar Symptoms'!$D$2:$D$57,C$11) -> 0 | D18: =COUNTIFS('Bipolar Symptoms'!$B$2:$B$57,$A18,'Bipolar Symptoms'!$D$2:$D$57,D$11) -> 0 | E18: =COUNTIFS('Bipolar Symptoms'!$B$2:$B$57,$A18,'Bipolar Symptoms'!$D$2:$D$57,E$11) -> 2
A19: Safety Check-in | B19: =COUNTIF('Bipolar Symptoms'!$B$2:$B$57,A19) -> 1 | C19: =COUNTIFS('Bipolar Symptoms'!$B$2:$B$57,$A19,'Bipolar Symptoms'!$D$2:$D$57,C$11) -> 0 | D19: =COUNTIFS('Bipolar Symptoms'!$B$2:$B$57,$A19,'Bipolar Symptoms'!$D$2:$D$57,D$11) -> 1 | E19: =COUNTIFS('Bipolar Symptoms'!$B$2:$B$57,$A19,'Bipolar Symptoms'!$D$2:$D$57,E$11) -> 0
A20: Energy, Body & Context | B20: =COUNTIF('Bipolar Symptoms'!$B$2:$B$57,A20) -> 12 | C20: =COUNTIFS('Bipolar Symptoms'!$B$2:$B$57,$A20,'Bipolar Symptoms'!$D$2:$D$57,C$11) -> 2 | D20: =COUNTIFS('Bipolar Symptoms'!$B$2:$B$57,$A20,'Bipolar Symptoms'!$D$2:$D$57,D$11) -> 6 | E20: =COUNTIFS('Bipolar Symptoms'!$B$2:$B$57,$A20,'Bipolar Symptoms'!$D$2:$D$57,E$11) -> 4
A21: Overall Check-in | B21: =COUNTIF('Bipolar Symptoms'!$B$2:$B$57,A21) -> 3 | C21: =COUNTIFS('Bipolar Symptoms'!$B$2:$B$57,$A21,'Bipolar Symptoms'!$D$2:$D$57,C$11) -> 2 | D21: =COUNTIFS('Bipolar Symptoms'!$B$2:$B$57,$A21,'Bipolar Symptoms'!$D$2:$D$57,D$11) -> 1 | E21: =COUNTIFS('Bipolar Symptoms'!$B$2:$B$57,$A21,'Bipolar Symptoms'!$D$2:$D$57,E$11) -> 0
A22: Total | B22: =SUM(B12:B21) -> 56 | C22: =SUM(C12:C21) -> 30 | D22: =SUM(D12:D21) -> 11 | E22: =SUM(E12:E21) -> 15

Sheet Cross-Reference
A1: Cross-reference: ADHD list vs Bipolar list
A2: 'Only' means no matching item exists in the other list in this workbook. It does not mean the symptom can never occur in the other condition. ADHD and bipolar disorder can also co-occur, and many symptoms overlap, so patterns over time matter more than any single item.
A4: At a glance
A5: Section | B5: Items | D5: Note
A6: ADHD only | B6: =COUNTIF($A$13:$A$102,A6) -> 26 | D6: In Section 3, one row can combine several items (for example, three ADHD restlessness items matching one bipolar agitation item), so row counts are lower than item counts.
A7: Bipolar only | B7: =COUNTIF($A$13:$A$102,A7) -> 21
A8: Either (overlapping symptom) | B8: =COUNTIF($A$13:$A$102,A8) -> 17
A9: General health / context | B9: =COUNTIF($A$13:$A$102,A9) -> 20
A10: Total rows | B10: =SUM(B6:B9) -> 84
A11: SECTION 1: Symptoms found only in the ADHD list
A12: Section | B12: ADHD ID(s) | C12: Bipolar ID(s) | D12: Category | E12: Symptom / Concept | F12: Input Type(s) | G12: How they differ / Notes
A13: ADHD only | B13: S003 | D13: Inattention | E13: Mind wandering during conversations or meetings | F13: ADHD: Slider | G13: DSM-5 inattention domain; No matching item in the bipolar list
A14: ADHD only | B14: S004 | D14: Inattention | E14: Zoned out when someone was talking to me | F14: ADHD: Radio | G14: DSM-5: 'does not seem to listen'; No matching item in the bipolar list
A15: ADHD only | B15: S005 | D15: Inattention | E15: Careless mistakes or missed details | F15: ADHD: Radio | G15: DSM-5 inattention domain; No matching item in the bipolar list
A16: ADHD only | B16: S006 | D16: Inattention | E16: Trouble finishing things I started | F16: ADHD: Slider | G16: DSM-5 inattention domain; No matching item in the bipolar list
A17: ADHD only | B17: S007 | D17: Inattention | E17: Avoided tasks that need sustained mental effort | F17: ADHD: Slider | G17: DSM-5 inattention domain; No matching item in the bipolar list
A18: ADHD only | B18: S008 | D18: Inattention | E18: Lost or misplaced something important | F18: ADHD: Checkbox | G18: DSM-5 inattention domain; No matching item in the bipolar list
A19: ADHD only | B19: S009 | D19: Inattention | E19: Forgot an appointment, task, or commitment | F19: ADHD: Checkbox | G19: DSM-5: forgetfulness in daily activities; No matching item in the bipolar list
A20: ADHD only | B20: S011 | D20: Inattention | E20: Hyperfocus (lost track of time on one thing) | F20: ADHD: Radio | G20: Not a DSM symptom, but common; useful for pattern spotting; No matching item in the bipolar list
A21: ADHD only | B21: S013 | D21: Executive Function | E21: Procrastination | F21: ADHD: Slider | G21: No matching item in the bipolar list
A22: ADHD only | B22: S014 | D22: Executive Function | E22: Trouble prioritizing what to do first | F22: ADHD: Slider | G22: No matching item in the bipolar list
A23: ADHD only | B23: S015 | D23: Executive Function | E23: Difficulty planning or organizing | F23: ADHD: Slider | G23: DSM-5: difficulty organizing tasks; No matching item in the bipolar list
A24: ADHD only | B24: S016 | D24: Executive Function | E24: Felt overwhelmed by the number of things to do | F24: ADHD: Slider | G24: No matching item in the bipolar list
... A38: ADHD only | B38: S063 | D38: Overall Check-in | E38: Overall focus | F38: ADHD: Slider | G38: Reverse-scored; No matching item in the bipolar list
A40: SECTION 2: Symptoms found only in the Bipolar list
A41: Section | B41: ADHD ID(s) | C41: Bipolar ID(s) | D41: Category | E41: Symptom / Concept | F41: Input Type(s) | G41: How they differ / Notes
A42: Bipolar only | C42: B001 | D42: Elevated Mood & Energy (Mania/Hypomania) | E42: Unusually happy, 'high,' or euphoric | F42: Bipolar: Slider | G42: DSM-5 manic/hypomanic episode: elevated or expansive mood
A43: Bipolar only | C43: B002 | D43: Elevated Mood & Energy (Mania/Hypomania) | E43: Felt unusually confident, powerful, or 'special' | F43: Bipolar: Slider | G43: DSM-5: inflated self-esteem or grandiosity
A44: Bipolar only | C44: B003 | D44: Elevated Mood & Energy (Mania/Hypomania) | E44: Much more energy than usual | F44: Bipolar: Slider | G44: DSM-5: increased energy or activity
A45: Bipolar only | C45: B004 | D45: Elevated Mood & Energy (Mania/Hypomania) | E45: Pushed hard on goals or projects (far more than usual) | F45: Bipolar: Slider | G45: DSM-5: increased goal-directed activity
A46: Bipolar only | C46: B005 | D46: Elevated Mood & Energy (Mania/Hypomania) | E46: Started several new projects or plans today | F46: Bipolar: Checkbox | G46: Easy to spot in hindsight; useful for pattern spotting
A47: Bipolar only | C47: B006 | D47: Elevated Mood & Energy (Mania/Hypomania) | E47: Unusually creative or inspired | F47: Bipolar: Slider | G47: Commonly reported in hypomania; not a diagnostic criterion
A48: Bipolar only | C48: B014 | D48: Thoughts & Speech | E48: Trouble making decisions | F48: Bipolar: Slider | G48: DSM-5 depressive episode: indecisiveness
A49: Bipolar only | C49: B015 | D49: Thoughts & Speech | E49: Others had trouble following what I was saying | F49: Bipolar: Checkbox | G49: Can reflect very fast or scattered speech
A50: Bipolar only | C50: B017 | D50: Sleep | E50: Needed much less sleep than usual but still felt energized | F50: Bipolar: Checkbox | G50: DSM-5: decreased need for sleep. Different from insomnia, where you want to sleep but can't
A51: Bipolar only | C51: B019 | D51: Sleep | E51: Slept much more than usual, or hard to get out of bed | F51: Bipolar: Checkbox | G51: DSM-5 depressive episode: hypersomnia
A52: Bipolar only | C52: B023 | D52: Risk-taking & Impulsivity | E52: Risky or reckless behavior (e.g., reckless driving, risky decisions) | F52: Bipolar: Checkbox | G52: DSM-5: excessive involvement in risky activities. ADHD impulsivity can look similar, but is typically ongoing rather than in episodes
A53: Bipolar only | C53: B024 | D53: Risk-taking & Impulsivity | E53: Increased sexual interest or activity | F53: Bipolar: Slider | G53: Listed in DSM-5 under risky activities (sexual indiscretions)
A54: Bipolar only | C54: B026 | D54: Depressed Mood | E54: Lost interest or pleasure in things I usually enjoy | F54: Bipolar: Slider | G54: DSM-5 depressive episode: anhedonia
A55: Bipolar only | C55: B027 | D55: Depressed Mood | E55: Felt hopeless about the future | F55: Bipolar: Slider
...
