Workbook

Sheet Read Me
A1: Mood Tracker Symptom Items: Anxiety, Schizophrenia and Depression
A3: What this is
A4: Starter lists of anxiety, schizophrenia, and depression symptoms plus general health items, each tagged with a suggested input type for a mood tracker app. It follows the same layout as the ADHD / Bipolar workbook, so the two can be combined. Edit freely: change wording, swap input types, or delete rows.
A6: Tabs
A7: Anxiety Symptoms: 53 items (worry, restlessness and focus, physical symptoms, panic attacks, social anxiety, avoidance, sleep, context, overall check-in).
A8: Schizophrenia Symptoms: 63 items (hallucinations, delusions, disorganized thinking and behavior, negative symptoms, cognitive symptoms, mood and sleep, early warning signs, safety check-in, context, overall check-in).
A9: Depression Symptoms: 56 items (mood, interest and pleasure, guilt and hopelessness, energy, concentration, sleep, appetite, physical symptoms, irritability and anxiety, withdrawal, safety check-in, context, overall check-in).
A10: Summary: counts by input type and by category for each of the three lists. The counts are formulas, so they update when you change a row.
A12: How the columns work
A13: Input Type: Slider = rate on a 0-10 scale; Radio = pick one option; Checkbox = tick if it happened today. Change it using the dropdown; the Summary tab updates automatically.
A14: Scale / Options: for sliders, the end labels; for radio, the options separated by ' | '; for checkboxes, what a tick means.
A15: Higher Score Means: whether a higher value is worse (symptom) or better (e.g. energy, sleep). Safety items say 'more concerning'. Context items are marked 'n/a (context)' and descriptive items 'n/a (descriptive)'.
... A26: Schizophrenia note: during an episode, people often cannot tell that a belief or experience is a symptom. Self-rated items may under-report, so the Schizophrenia list includes items about what other people have noticed, and works best alongside a care team or a trusted support person.

Sheet Anxiety Symptoms
A1: ID | B1: Category | C1: Symptom / Prompt (as shown in app) | D1: Input Type | E1: Scale / Options | F1: Higher Score Means | G1: Notes
A2: AX001 | B2: Worry & Anxious Thoughts | C2: Worry about everyday things (work, health, money, family) | D2: Slider | E2: 0 = Not at all, 10 = Severe | F2: Higher = more symptom | G2: DSM-5 GAD: excessive worry; NIMH: 'worry excessively about everyday things'
A3: AX002 | B3: Worry & Anxious Thoughts | C3: Difficulty controlling or stopping my worrying | D3: Slider | E3: 0 = Not at all, 10 = Severe | F3: Higher = more symptom | G3: DSM-5 GAD: difficulty controlling the worry; NIMH
A4: AX003 | B4: Worry & Anxious Thoughts | C4: Worry felt out of proportion to the situation | D4: Radio | E4: Not at all | Somewhat | Mostly | Completely | F4: Higher = more symptom | G4: DSM-5 GAD: worry out of proportion to the actual risk
A5: AX004 | B5: Worry & Anxious Thoughts | C5: Felt nervous or anxious, even without a clear reason | D5: Slider | E5: 0 = Not at all, 10 = Severe | F5: Higher = more symptom | G5: NIMH: feelings of nervousness
A6: AX005 | B6: Worry & Anxious Thoughts | C6: Expected the worst outcome ('what if' thinking) | D6: Slider | E6: 0 = Not at all, 10 = Severe | F6: Higher = more symptom | G6: Catastrophizing; NIMH lists 'expect the worst' for social anxiety, common across anxiety disorders
A7: AX006 | B7: Worry & Anxious Thoughts | C7: Felt a sense of dread or that something bad was about to happen | D7: Slider | E7: 0 = Not at all, 10 = Severe | F7: Higher = more symptom | G7: NIMH panic disorder: fear of impending doom; also common in generalized anxiety
A8: AX007 | B8: Worry & Anxious Thoughts | C8: Worried about when the next panic attack might happen | D8: Slider | E8: 0 = Not at all, 10 = Severe | F8: Higher = more symptom | G8: NIMH panic disorder: intense worry about the next attack
A9: AX008 | B9: Restlessness, Irritability & Focus | C9: Felt restless, keyed up, or on edge | D9: Slider | E9: 0 = Not at all, 10 = Severe | F9: Higher = more symptom | G9: DSM-5 GAD criterion; NIMH
A10: AX009 | B10: Restlessness, Irritability & Focus | C10: Trouble relaxing | D10: Slider | E10: 0 = Not at all, 10 = Severe | F10: Higher = more symptom | G10: NIMH: 'trouble relaxing'
A11: AX010 | B11: Restlessness, Irritability & Focus | C11: Irritable or short-tempered | D11: Slider | E11: 0 = Not at all, 10 = Severe | F11: Higher = more symptom | G11: DSM-5 GAD criterion; NIMH
A12: AX011 | B12: Restlessness, Irritability & Focus | C12: Trouble concentrating, or my mind went blank | D12: Slider | E12: 0 = Not at all, 10 = Severe | F12: Higher = more symptom | G12: DSM-5 GAD criterion; NIMH social anxiety: 'mind going blank'
... A54: AX053 | B54: Overall Check-in | C54: Overall mood | D54: Radio | E54: Very low | Low | Okay | Good | Very good | F54: Higher = better | G54: Quick summary rating

Sheet Schizophrenia Symptoms
A1: ID | B1: Category | C1: Symptom / Prompt (as shown in app) | D1: Input Type | E1: Scale / Options | F1: Higher Score Means | G1: Notes
A2: SZ001 | B2: Hallucinations | C2: Heard voices or sounds that other people couldn't hear | D2: Radio | E2: Not at all | Briefly | Several times | Most of the day | F2: Higher = more symptom | G2: DSM-5 criterion A: hallucinations; NIMH: hearing voices is common
A3: SZ002 | B3: Hallucinations | C3: Voices commented on me or criticized me | D3: Checkbox | E3: Checked = happened today | F3: Higher = more symptom | G3: NIMH psychosis: voices that criticize. Voices that give commands are asked about under Safety Check-in
A4: SZ003 | B4: Hallucinations | C4: How distressing the voices or sounds were | D4: Slider | E4: 0 = Not at all, 10 = Severe | F4: Higher = more symptom | G4: Distress is useful for pattern spotting and clinician review
A5: SZ004 | B5: Hallucinations | C5: Saw things that other people couldn't see | D5: Radio | E5: Not at all | Briefly | Several times | Most of the day | F5: Higher = more symptom | G5: DSM-5 criterion A: hallucinations (any sense); NIMH
A6: SZ005 | B6: Hallucinations | C6: Unusual smells, tastes, or touch sensations with no clear cause | D6: Checkbox | E6: Checked = happened today | F6: Higher = more symptom | G6: DSM-5: hallucinations can involve any sense; less common than voices
A7: SZ006 | B7: Hallucinations | C7: Unsure whether something I saw or heard was real | D7: Slider | E7: 0 = Not at all, 10 = Severe | F7: Higher = more symptom | G7: NIMH early signs: trouble telling what is real from what is imagined
A8: SZ007 | B8: Delusions & Unusual Beliefs | C8: Felt suspicious, watched, followed, or talked about | D8: Slider | E8: 0 = Not at all, 10 = Severe | F8: Higher = more symptom | G8: DSM-5 delusions (persecutory type is the most common); NIMH: growing suspicion
A9: SZ008 | B9: Delusions & Unusual Beliefs | C9: Believed others were trying to harm me | D9: Slider | E9: 0 = Not at all, 10 = Severe | F9: Higher = more symptom | G9: NIMH delusions: believing others are trying to hurt them
A10: SZ009 | B10: Delusions & Unusual Beliefs | C10: Felt TV, radio, or messages had a special meaning meant for me | D10: Checkbox | E10: Checked = happened today | F10: Higher = more symptom | G10: NIMH delusions: broadcasts holding special messages that require a response (ideas of reference)
A11: SZ010 | B11: Delusions & Unusual Beliefs | C11: Felt my thoughts were being controlled, put in, taken out, or broadcast | D11: Slider | E11: 0 = Not at all, 10 = Severe | F11: Higher = more symptom | G11: Recognized delusion theme in DSM-5 text (thought insertion / broadcasting)
A12: SZ011 | B12: Delusions & Unusual Beliefs | C12: Felt an outside force was controlling my body or actions | D12: Slider | E12: 0 = Not at all, 10 = Severe | F12: Higher = more symptom | G12: Recognized delusion theme in DSM-5 text (delusions of control)
... A64: SZ063 | B64: Overall Check-in | C64: Overall mood | D64: Radio | E64: Very low | Low | Okay | Good | Very good | F64: Higher = better | G64: Quick summary rating

Sheet Depression Symptoms
A1: ID | B1: Category | C1: Symptom / Prompt (as shown in app) | D1: Input Type | E1: Scale / Options | F1: Higher Score Means | G1: Notes
A2: DP001 | B2: Depressed Mood | C2: Felt sad, down, or empty | D2: Slider | E2: 0 = Not at all, 10 = Severe | F2: Higher = more symptom | G2: DSM-5 MDD criterion 1: depressed mood; NIMH: persistent sad, anxious, or 'empty' mood
A3: DP002 | B3: Depressed Mood | C3: Low mood lasted | D3: Radio | E3: Not at all | Part of the day | Most of the day | All day | F3: Higher = more symptom | G3: DSM-5 requires depressed mood most of the day, nearly every day, for 2 weeks; this is a daily proxy
A4: DP003 | B4: Depressed Mood | C4: Tearful or close to tears | D4: Slider | E4: 0 = Not at all, 10 = Severe | F4: Higher = more symptom | G4: DSM-5 MDD: tearful appearance can show depressed mood
A5: DP004 | B5: Depressed Mood | C5: Felt numb or emotionally flat | D5: Slider | E5: 0 = Not at all, 10 = Severe | F5: Higher = more symptom | G5: Commonly reported; not a DSM-5 criterion
A6: DP005 | B6: Depressed Mood | C6: Mood was worst in the | D6: Radio | E6: No pattern | Morning | Afternoon | Evening | F6: n/a (descriptive) | G6: Daily pattern (diurnal variation); descriptive, useful for pattern spotting
A7: DP006 | B7: Loss of Interest & Pleasure | C7: Little interest or pleasure in things I usually enjoy | D7: Slider | E7: 0 = Not at all, 10 = Severe | F7: Higher = more symptom | G7: DSM-5 MDD criterion 2; NIMH: loss of interest or pleasure in hobbies and activities
A8: DP007 | B8: Loss of Interest & Pleasure | C8: Hard to get started on activities I normally like | D8: Slider | E8: 0 = Not at all, 10 = Severe | F8: Higher = more symptom | G8: NIMH; anhedonia and low drive
A9: DP008 | B9: Loss of Interest & Pleasure | C9: Did something I normally enjoy | D9: Checkbox | E9: Checked = happened today | F9: Higher = better | G9: Protective item; helps with behavioral activation
A10: DP009 | B10: Loss of Interest & Pleasure | C10: Less interest in sex or closeness | D10: Slider | E10: 0 = Not at all, 10 = Severe | F10: Higher = more symptom | G10: NIMH: changes in sexual desire or performance
A11: DP010 | B11: Guilt, Worthlessness & Hopelessness | C11: Felt worthless or like a failure | D11: Slider | E11: 0 = Not at all, 10 = Severe | F11: Higher = more symptom | G11: DSM-5 MDD criterion 7; NIMH: feelings of worthlessness
A12: DP011 | B12: Guilt, Worthlessness & Hopelessness | C12: Felt excessive or unreasonable guilt | D12: Slider | E12: 0 = Not at all, 10 = Severe | F12: Higher = more symptom | G12: DSM-5 MDD criterion 7: excessive or inappropriate guilt
... A57: DP056 | B57: Overall Check-in | C57: Overall functioning today (work, home, relationships) | D57: Slider | E57: 0 = Very poor, 10 = Excellent | F57: Higher = better | G57: Reverse-scored: higher is better

Sheet Summary
A1: Symptom counts
A3: Anxiety
A4: By input type
A5: Input Type | B5: Count
A6: Slider | B6: =COUNTIF('Anxiety Symptoms'!$D$2:$D$54,A6) -> 33
A7: Radio | B7: =COUNTIF('Anxiety Symptoms'!$D$2:$D$54,A7) -> 8
A8: Checkbox | B8: =COUNTIF('Anxiety Symptoms'!$D$2:$D$54,A8) -> 12
A9: Total | B9: =SUM(B6:B8) -> 53
A11: By category
A12: Category | B12: Total | C12: Slider | D12: Radio | E12: Checkbox
A13: Worry & Anxious Thoughts | B13: =COUNTIF('Anxiety Symptoms'!$B$2:$B$54,A13) -> 7 | C13: =COUNTIFS('Anxiety Symptoms'!$B$2:$B$54,$A13,'Anxiety Symptoms'!$D$2:$D$54,C$12) -> 6 | D13: =COUNTIFS('Anxiety Symptoms'!$B$2:$B$54,$A13,'Anxiety Symptoms'!$D$2:$D$54,D$12) -> 1 | E13: =COUNTIFS('Anxiety Symptoms'!$B$2:$B$54,$A13,'Anxiety Symptoms'!$D$2:$D$54,E$12) -> 0
A14: Restlessness, Irritability & Focus | B14: =COUNTIF('Anxiety Symptoms'!$B$2:$B$54,A14) -> 6 | C14: =COUNTIFS('Anxiety Symptoms'!$B$2:$B$54,$A14,'Anxiety Symptoms'!$D$2:$D$54,C$12) -> 6 | D14: =COUNTIFS('Anxiety Symptoms'!$B$2:$B$54,$A14,'Anxiety Symptoms'!$D$2:$D$54,D$12) -> 0 | E14: =COUNTIFS('Anxiety Symptoms'!$B$2:$B$54,$A14,'Anxiety Symptoms'!$D$2:$D$54,E$12) -> 0
A15: Physical Symptoms | B15: =COUNTIF('Anxiety Symptoms'!$B$2:$B$54,A15) -> 8 | C15: =COUNTIFS('Anxiety Symptoms'!$B$2:$B$54,$A15,'Anxiety Symptoms'!$D$2:$D$54,C$12) -> 7 | D15: =COUNTIFS('Anxiety Symptoms'!$B$2:$B$54,$A15,'Anxiety Symptoms'!$D$2:$D$54,D$12) -> 0 | E15: =COUNTIFS('Anxiety Symptoms'!$B$2:$B$54,$A15,'Anxiety Symptoms'!$D$2:$D$54,E$12) -> 1
A16: Panic Attacks | B16: =COUNTIF('Anxiety Symptoms'!$B$2:$B$54,A16) -> 8 | C16: =COUNTIFS('Anxiety Symptoms'!$B$2:$B$54,$A16,'Anxiety Symptoms'!$D$2:$D$54,C$12) -> 4 | D16: =COUNTIFS('Anxiety Symptoms'!$B$2:$B$54,$A16,'Anxiety Symptoms'!$D$2:$D$54,D$12) -> 0 | E16: =COUNTIFS('Anxiety Symptoms'!$B$2:$B$54,$A16,'Anxiety Symptoms'!$D$2:$D$54,E$12) -> 4
A17: Social Anxiety | B17: =COUNTIF('Anxiety Symptoms'!$B$2:$B$54,A17) -> 5 | C17: =COUNTIFS('Anxiety Symptoms'!$B$2:$B$54,$A17,'Anxiety Symptoms'!$D$2:$D$54,C$12) -> 5 | D17: =COUNTIFS('Anxiety Symptoms'!$B$2:$B$54,$A17,'Anxiety Symptoms'!$D$2:$D$54,D$12) -> 0 | E17: =COUNTIFS('Anxiety Symptoms'!$B$2:$B$54,$A17,'Anxiety Symptoms'!$D$2:$D$54,E$12) -> 0
A18: Avoidance & Safety Behaviors | B18: =COUNTIF('Anxiety Symptoms'!$B$2:$B$54,A18) -> 5 | C18: =COUNTIFS('Anxiety Symptoms'!$B$2:$B$54,$A18,'Anxiety Symptoms'!$D$2:$D$54,C$12) -> 1 | D18: =COUNTIFS('Anxiety Symptoms'!$B$2:$B$54,$A18,'Anxiety Symptoms'!$D$2:$D$54,D$12) -> 1 | E18: =COUNTIFS('Anxiety Symptoms'!$B$2:$B$54,$A18,'Anxiety Symptoms'!$D$2:$D$54,E$12) -> 3
A19: Sleep | B19: =COUNTIF('Anxiety Symptoms'!$B$2:$B$54,A19) -> 4 | C19: =COUNTIFS('Anxiety Symptoms'!$B$2:$B$54,$A19,'Anxiety Symptoms'!$D$2:$D$54,C$12) -> 2 | D19: =COUNTIFS('Anxiety Symptoms'!$B$2:$B$54,$A19,'Anxiety Symptoms'!$D$2:$D$54,D$12) -> 1 | E19: =COUNTIFS('Anxiety Symptoms'!$B$2:$B$54,$A19,'Anxiety Symptoms'!$D$2:$D$54,E$12) -> 1
A20: Context & Coping | B20: =COUNTIF('Anxiety Symptoms'!$B$2:$B$54,A20) -> 7 | C20: =COUNTIFS('Anxiety Symptoms'!$B$2:$B$54,$A20,'Anxiety Symptoms'!$D$2:$D$54,C$12) -> 0 | D20: =COUNTIFS('Anxiety Symptoms'!$B$2:$B$54,$A20,'Anxiety Symptoms'!$D$2:$D$54,D$12) -> 4 | E20: =COUNTIFS('Anxiety Symptoms'!$B$2:$B$54,$A20,'Anxiety Symptoms'!$D$2:$D$54,E$12) -> 3
A21: Overall Check-in | B21: =COUNTIF('Anxiety Symptoms'!$B$2:$B$54,A21) -> 3 | C21: =COUNTIFS('Anxiety Symptoms'!$B$2:$B$54,$A21,'Anxiety Symptoms'!$D$2:$D$54,C$12) -> 2 | D21: =COUNTIFS('Anxiety Symptoms'!$B$2:$B$54,$A21,'Anxiety Symptoms'!$D$2:$D$54,D$12) -> 1 | E21: =COUNTIFS('Anxiety Symptoms'!$B$2:$B$54,$A21,'Anxiety Symptoms'!$D$2:$D$54,E$12) -> 0
A22: Total | B22: =SUM(B13:B21) -> 53 | C22: =SUM(C13:C21) -> 33 | D22: =SUM(D13:D21) -> 8 | E22: =SUM(E13:E21) -> 12
A25: Schizophrenia
A26: By input type
A27: Input Type | B27: Count
A28: Slider | B28: =COUNTIF('Schizophrenia Symptoms'!$D$2:$D$64,A28) -> 35
A29: Radio | B29: =COUNTIF('Schizophrenia Symptoms'!$D$2:$D$64,A29) -> 12
A30: Checkbox | B30: =COUNTIF('Schizophrenia Symptoms'!$D$2:$D$64,A30) -> 16
A31: Total | B31: =SUM(B28:B30) -> 63
A33: By category
A34: Category | B34: Total | C34: Slider | D34: Radio | E34: Checkbox
A35: Hallucinations | B35: =COUNTIF('Schizophrenia Symptoms'!$B$2:$B$64,A35) -> 6 | C35: =COUNTIFS('Schizophrenia Symptoms'!$B$2:$B$64,$A35,'Schizophrenia Symptoms'!$D$2:$D$64,C$34) -> 2 | D35: =COUNTIFS('Schizophrenia Symptoms'!$B$2:$B$64,$A35,'Schizophrenia Symptoms'!$D$2:$D$64,D$34) -> 2 | E35: =COUNTIFS('Schizophrenia Symptoms'!$B$2:$B$64,$A35,'Schizophrenia Symptoms'!$D$2:$D$64,E$34) -> 2
A36: Delusions & Unusual Beliefs | B36: =COUNTIF('Schizophrenia Symptoms'!$B$2:$B$64,A36) -> 8 | C36: =COUNTIFS('Schizophrenia Symptoms'!$B$2:$B$64,$A36,'Schizophrenia Symptoms'!$D$2:$D$64,C$34) -> 6 | D36: =COUNTIFS('Schizophrenia Symptoms'!$B$2:$B$64,$A36,'Schizophrenia Symptoms'!$D$2:$D$64,D$34) -> 0 | E36: =COUNTIFS('Schizophrenia Symptoms'!$B$2:$B$64,$A36,'Schizophrenia Symptoms'!$D$2:$D$64,E$34) -> 2
A37: Disorganized Thinking & Speech | B37: =COUNTIF('Schizophrenia Symptoms'!$B$2:$B$64,A37) -> 5 | C37: =COUNTIFS('Schizophrenia Symptoms'!$B$2:$B$64,$A37,'Schizophrenia Symptoms'!$D$2:$D$64,C$34) -> 2 | D37: =COUNTIFS('Schizophrenia Symptoms'!$B$2:$B$64,$A37,'Schizophrenia Symptoms'!$D$2:$D$64,D$34) -> 1 | E37: =COUNTIFS('Schizophrenia Symptoms'!$B$2:$B$64,$A37,'Schizophrenia Symptoms'!$D$2:$D$64,E$34) -> 2
A38: Disorganized or Unusual Behavior | B38: =COUNTIF('Schizophrenia Symptoms'!$B$2:$B$64,A38) -> 3 | C38: =COUNTIFS('Schizophrenia Symptoms'!$B$2:$B$64,$A38,'Schizophrenia Symptoms'!$D$2:$D$64,C$34) -> 1 | D38: =COUNTIFS('Schizophrenia Symptoms'!$B$2:$B$64,$A38,'Schizophrenia Symptoms'!$D$2:$D$64,D$34) -> 0 | E38: =COUNTIFS('Schizophrenia Symptoms'!$B$2:$B$64,$A38,'Schizophrenia Symptoms'!$D$2:$D$64,E$34) -> 2
A39: Negative: Motivation & Pleasure | B39: =COUNTIF('Schizophrenia Symptoms'!$B$2:$B$64,A39) -> 6 | C39: =COUNTIFS('Schizophrenia Symptoms'!$B$2:$B$64,$A39,'Schizophrenia Symptoms'!$D$2:$D$64,C$34) -> 5 | D39: =COUNTIFS('Schizophrenia Symptoms'!$B$2:$B$64,$A39,'Schizophrenia Symptoms'!$D$2:$D$64,D$34) -> 1 | E39: =COUNTIFS('Schizophrenia Symptoms'!$B$2:$B$64,$A39,'Schizophrenia Symptoms'!$D$2:$D$64,E$34) -> 0
A40: Negative: Expression & Social | B40: =COUNTIF('Schizophrenia Symptoms'!$B$2:$B$64,A40) -> 6 | C40: =COUNTIFS('Schizophrenia Symptoms'!$B$2:$B$64,$A40,'Schizophrenia Symptoms'!$D$2:$D$64,C$34) -> 4 | D40: =COUNTIFS('Schizophrenia Symptoms'!$B$2:$B$64,$A40,'Schizophrenia Symptoms'!$D$2:$D$64,D$34) -> 1 | E40: =COUNTIFS('Schizophrenia Symptoms'!$B$2:$B$64,$A40,'Schizophrenia Symptoms'!$D$2:$D$64,E$34) -> 1
A41: Cognitive Symptoms | B41: =COUNTIF('Schizophrenia Symptoms'!$B$2:$B$64,A41) -> 6 | C41: =COUNTIFS('Schizophrenia Symptoms'!$B$2:$B$64,$A41,'Schizophrenia Symptoms'!$D$2:$D$64,C$34) -> 6 | D41: =COUNTIFS('Schizophrenia Symptoms'!$B$2:$B$64,$A41,'Schizophrenia Symptoms'!$D$2:$D$64,D$34) -> 0 | E41: =COUNTIFS('Schizophrenia Symptoms'!$B$2:$B$64,$A41,'Schizophrenia Symptoms'!$D$2:$D$64,E$34) -> 0
A42: Mood, Anxiety & Sleep | B42: =COUNTIF('Schizophrenia Symptoms'!$B$2:$B$64,A42) -> 6 | C42: =COUNTIFS('Schizophrenia Symptoms'!$B$2:$B$64,$A42,'Schizophrenia Symptoms'!$D$2:$D$64,C$34) -> 5 | D42: =COUNTIFS('Schizophrenia Symptoms'!$B$2:$B$64,$A42,'Schizophrenia Symptoms'!$D$2:$D$64,D$34) -> 1 | E42: =COUNTIFS('Schizophrenia Symptoms'!$B$2:$B$64,$A42,'Schizophrenia Symptoms'!$D$2:$D$64,E$34) -> 0
A43: Early Warning Signs | B43: =COUNTIF('Schizophrenia Symptoms'!$B$2:$B$64,A43) -> 5 | C43: =COUNTIFS('Schizophrenia Symptoms'!$B$2:$B$64,$A43,'Schizophrenia Symptoms'!$D$2:$D$64,C$34) -> 2 | D43: =COUNTIFS('Schizophrenia Symptoms'!$B$2:$B$64,$A43,'Schizophrenia Symptoms'!$D$2:$D$64,D$34) -> 0 | E43: =COUNTIFS('Schizophrenia Symptoms'!$B$2:$B$64,$A43,'Schizophrenia Symptoms'!$D$2:$D$64,E$34) -> 3
A44: Safety Check-in | B44: =COUNTIF('Schizophrenia Symptoms'!$B$2:$B$64,A44) -> 2 | C44: =COUNTIFS('Schizophrenia Symptoms'!$B$2:$B$64,$A44,'Schizophrenia Symptoms'!$D$2:$D$64,C$34) -> 0 | D44: =COUNTIFS('Schizophrenia Symptoms'!$B$2:$B$64,$A44,'Schizophrenia Symptoms'!$D$2:$D$64,D$34) -> 2 | E44: =COUNTIFS('Schizophrenia Symptoms'!$B$2:$B$64,$A44,'Schizophrenia Symptoms'!$D$2:$D$64,E$34) -> 0
A45: Context & Treatment | B45: =COUNTIF('Schizophrenia Symptoms'!$B$2:$B$64,A45) -> 7 | C45: =COUNTIFS('Schizophrenia Symptoms'!$B$2:$B$64,$A45,'Schizophrenia Symptoms'!$D$2:$D$64,C$34) -> 0 | D45: =COUNTIFS('Schizophrenia Symptoms'!$B$2:$B$64,$A45,'Schizophrenia Symptoms'!$D$2:$D$64,D$34) -> 3 | E45: =COUNTIFS('Schizophrenia Symptoms'!$B$2:$B$64,$A45,'Schizophrenia Symptoms'!$D$2:$D$64,E$34) -> 4
...
